.
----------------------------------------------------------------------
Ran 1 test in 5.994s

OK
FFFFFFFFFFF
======================================================================
FAIL: test_forward_lookup (rnvs_tb.blocks.block5.PeerTestCase)
Test whether the peer forwards lookup requests correctly on the ring.
----------------------------------------------------------------------
Traceback (most recent call last):
  File "/usr/local/lib/python3.10/dist-packages/rnvs_tb/common.py", line 36, in log_wrapper
    return fun(*args, **kwargs)
  File "/usr/local/lib/python3.10/dist-packages/rnvs_tb/blocks/block5.py", line 270, in test_forward_lookup
    self.fail(f"Peer did not forward lookup to successor! Stdout: {out}, Stderr:{err}")
AssertionError: Peer did not forward lookup to successor! Stdout: bytearray(b''), Stderr:bytearray(b'Starting server. Press any key to exit.\nDecoded control packet header: \n\tJOIN: 0\n\tNOTIFY: 0\n\tSTABILIZE: 0\n\tLOOKUP: 1\n\tREPLY: 0\nHandling control packet...\nLol! This should not happen!\n')

======================================================================
FAIL: test_get_full_circle (rnvs_tb.blocks.block5.PeerTestCase)
Tests a full sequence for client GET request that needs to be fetched from another node.
----------------------------------------------------------------------
Traceback (most recent call last):
  File "/usr/local/lib/python3.10/dist-packages/rnvs_tb/common.py", line 36, in log_wrapper
    return fun(*args, **kwargs)
  File "/usr/local/lib/python3.10/dist-packages/rnvs_tb/blocks/block5.py", line 341, in test_get_full_circle
    self.fail(f"Did not receive a Lookup request within timeout! Stdout: {out}, Stderr:{err}")
AssertionError: Did not receive a Lookup request within timeout! Stdout: bytearray(b''), Stderr:bytearray(b'Starting server. Press any key to exit.\nDecoded packet header: \n\tACK: 0\n\tGET: 1\n\tSET: 0\n\tDEL: 0\n\tKey Length: 23 Bytes\n\tValue Length: 0 Bytes\nHash id: 21608\nWe are responsible.\n')

======================================================================
FAIL: test_student_ring_long_fixed_buffer (rnvs_tb.blocks.block5.PeerTestCase)
Test SET-GET on the ring for long values.
----------------------------------------------------------------------
Traceback (most recent call last):
  File "/usr/local/lib/python3.10/dist-packages/rnvs_tb/mock.py", line 153, in run
    response = self.packet.__class__.parse(reply)
  File "/usr/local/lib/python3.10/dist-packages/rnvs_tb/packet.py", line 56, in parse
    key_len, value_len = cls.len_from_header(buffer)
  File "/usr/local/lib/python3.10/dist-packages/rnvs_tb/packet.py", line 40, in len_from_header
    raise ValueError(f'Header too short! Expected 7 bytes but got only {len(buffer)}!')
ValueError: Header too short! Expected 7 bytes but got only 0!

The above exception was the direct cause of the following exception:

Traceback (most recent call last):
  File "/usr/local/lib/python3.10/dist-packages/rnvs_tb/common.py", line 36, in log_wrapper
    return fun(*args, **kwargs)
  File "/usr/local/lib/python3.10/dist-packages/rnvs_tb/blocks/block5.py", line 646, in test_student_ring_long_fixed_buffer
    c1.await_packet(timeout=2.0)  # Wait for ACK before we query 2nd time
  File "/usr/local/lib/python3.10/dist-packages/rnvs_tb/mock.py", line 105, in await_packet
    raise AssertionError('Did not receive expected packet due to previous errors!') from value
AssertionError: Did not receive expected packet due to previous errors!

======================================================================
FAIL: test_student_ring_long_value (rnvs_tb.blocks.block5.PeerTestCase)
Test SET-GET on the ring for long values.
----------------------------------------------------------------------
Traceback (most recent call last):
  File "/usr/local/lib/python3.10/dist-packages/rnvs_tb/mock.py", line 153, in run
    response = self.packet.__class__.parse(reply)
  File "/usr/local/lib/python3.10/dist-packages/rnvs_tb/packet.py", line 56, in parse
    key_len, value_len = cls.len_from_header(buffer)
  File "/usr/local/lib/python3.10/dist-packages/rnvs_tb/packet.py", line 40, in len_from_header
    raise ValueError(f'Header too short! Expected 7 bytes but got only {len(buffer)}!')
ValueError: Header too short! Expected 7 bytes but got only 0!

The above exception was the direct cause of the following exception:

Traceback (most recent call last):
  File "/usr/local/lib/python3.10/dist-packages/rnvs_tb/common.py", line 36, in log_wrapper
    return fun(*args, **kwargs)
  File "/usr/local/lib/python3.10/dist-packages/rnvs_tb/blocks/block5.py", line 600, in test_student_ring_long_value
    c1.await_packet(timeout=2.0)  # Wait for ACK before we query 2nd time
  File "/usr/local/lib/python3.10/dist-packages/rnvs_tb/mock.py", line 105, in await_packet
    raise AssertionError('Did not receive expected packet due to previous errors!') from value
AssertionError: Did not receive expected packet due to previous errors!

======================================================================
FAIL: test_student_ring_set_del_set_get (rnvs_tb.blocks.block5.PeerTestCase)
Test SET-DELETE followed by SET-GET  on the same key among multiple instances of the student's peer.
----------------------------------------------------------------------
Traceback (most recent call last):
  File "/usr/local/lib/python3.10/dist-packages/rnvs_tb/mock.py", line 153, in run
    response = self.packet.__class__.parse(reply)
  File "/usr/local/lib/python3.10/dist-packages/rnvs_tb/packet.py", line 56, in parse
    key_len, value_len = cls.len_from_header(buffer)
  File "/usr/local/lib/python3.10/dist-packages/rnvs_tb/packet.py", line 40, in len_from_header
    raise ValueError(f'Header too short! Expected 7 bytes but got only {len(buffer)}!')
ValueError: Header too short! Expected 7 bytes but got only 0!

The above exception was the direct cause of the following exception:

Traceback (most recent call last):
  File "/usr/local/lib/python3.10/dist-packages/rnvs_tb/common.py", line 36, in log_wrapper
    return fun(*args, **kwargs)
  File "/usr/local/lib/python3.10/dist-packages/rnvs_tb/blocks/block5.py", line 501, in test_student_ring_set_del_set_get
    c1.await_packet(timeout=2.0)  # Wait for ACK before we query 2nd time
  File "/usr/local/lib/python3.10/dist-packages/rnvs_tb/mock.py", line 105, in await_packet
    raise AssertionError('Did not receive expected packet due to previous errors!') from value
AssertionError: Did not receive expected packet due to previous errors!

======================================================================
FAIL: test_student_ring_set_get_basic (rnvs_tb.blocks.block5.PeerTestCase)
Test simple SET-GET sequence among multiple instances of the student's peer.
----------------------------------------------------------------------
Traceback (most recent call last):
  File "/usr/local/lib/python3.10/dist-packages/rnvs_tb/mock.py", line 153, in run
    response = self.packet.__class__.parse(reply)
  File "/usr/local/lib/python3.10/dist-packages/rnvs_tb/packet.py", line 56, in parse
    key_len, value_len = cls.len_from_header(buffer)
  File "/usr/local/lib/python3.10/dist-packages/rnvs_tb/packet.py", line 40, in len_from_header
    raise ValueError(f'Header too short! Expected 7 bytes but got only {len(buffer)}!')
ValueError: Header too short! Expected 7 bytes but got only 0!

The above exception was the direct cause of the following exception:

Traceback (most recent call last):
  File "/usr/local/lib/python3.10/dist-packages/rnvs_tb/common.py", line 36, in log_wrapper
    return fun(*args, **kwargs)
  File "/usr/local/lib/python3.10/dist-packages/rnvs_tb/blocks/block5.py", line 446, in test_student_ring_set_get_basic
    c1.await_packet(timeout=2.0)  # Wait for ACK before we query 2nd time
  File "/usr/local/lib/python3.10/dist-packages/rnvs_tb/mock.py", line 105, in await_packet
    raise AssertionError('Did not receive expected packet due to previous errors!') from value
AssertionError: Did not receive expected packet due to previous errors!

======================================================================
FAIL: test_student_ring_set_get_cross_zero (rnvs_tb.blocks.block5.PeerTestCase)
Test simple SET-GET sequence among multiple instances of the student's peer reaching across zero.
----------------------------------------------------------------------
Traceback (most recent call last):
  File "/usr/local/lib/python3.10/dist-packages/rnvs_tb/mock.py", line 153, in run
    response = self.packet.__class__.parse(reply)
  File "/usr/local/lib/python3.10/dist-packages/rnvs_tb/packet.py", line 56, in parse
    key_len, value_len = cls.len_from_header(buffer)
  File "/usr/local/lib/python3.10/dist-packages/rnvs_tb/packet.py", line 40, in len_from_header
    raise ValueError(f'Header too short! Expected 7 bytes but got only {len(buffer)}!')
ValueError: Header too short! Expected 7 bytes but got only 0!

The above exception was the direct cause of the following exception:

Traceback (most recent call last):
  File "/usr/local/lib/python3.10/dist-packages/rnvs_tb/common.py", line 36, in log_wrapper
    return fun(*args, **kwargs)
  File "/usr/local/lib/python3.10/dist-packages/rnvs_tb/blocks/block5.py", line 789, in test_student_ring_set_get_cross_zero
    c1.await_packet(timeout=2.0)  # Wait for ACK before we query 2nd time
  File "/usr/local/lib/python3.10/dist-packages/rnvs_tb/mock.py", line 105, in await_packet
    raise AssertionError('Did not receive expected packet due to previous errors!') from value
AssertionError: Did not receive expected packet due to previous errors!

======================================================================
FAIL: test_student_ring_set_get_null (rnvs_tb.blocks.block5.PeerTestCase)
Test handling of  -bytes (a third time) on the Chord ring.
----------------------------------------------------------------------
Traceback (most recent call last):
  File "/usr/local/lib/python3.10/dist-packages/rnvs_tb/mock.py", line 153, in run
    response = self.packet.__class__.parse(reply)
  File "/usr/local/lib/python3.10/dist-packages/rnvs_tb/packet.py", line 56, in parse
    key_len, value_len = cls.len_from_header(buffer)
  File "/usr/local/lib/python3.10/dist-packages/rnvs_tb/packet.py", line 40, in len_from_header
    raise ValueError(f'Header too short! Expected 7 bytes but got only {len(buffer)}!')
ValueError: Header too short! Expected 7 bytes but got only 0!

The above exception was the direct cause of the following exception:

Traceback (most recent call last):
  File "/usr/local/lib/python3.10/dist-packages/rnvs_tb/common.py", line 36, in log_wrapper
    return fun(*args, **kwargs)
  File "/usr/local/lib/python3.10/dist-packages/rnvs_tb/blocks/block5.py", line 682, in test_student_ring_set_get_null
    c1.await_packet(timeout=2.0)  # Wait for ACK before we query 2nd time
  File "/usr/local/lib/python3.10/dist-packages/rnvs_tb/mock.py", line 105, in await_packet
    raise AssertionError('Did not receive expected packet due to previous errors!') from value
AssertionError: Did not receive expected packet due to previous errors!

======================================================================
FAIL: test_student_ring_set_set_get (rnvs_tb.blocks.block5.PeerTestCase)
Test overwriting of values on the Chord ring.
----------------------------------------------------------------------
Traceback (most recent call last):
  File "/usr/local/lib/python3.10/dist-packages/rnvs_tb/mock.py", line 153, in run
    response = self.packet.__class__.parse(reply)
  File "/usr/local/lib/python3.10/dist-packages/rnvs_tb/packet.py", line 56, in parse
    key_len, value_len = cls.len_from_header(buffer)
  File "/usr/local/lib/python3.10/dist-packages/rnvs_tb/packet.py", line 40, in len_from_header
    raise ValueError(f'Header too short! Expected 7 bytes but got only {len(buffer)}!')
ValueError: Header too short! Expected 7 bytes but got only 0!

The above exception was the direct cause of the following exception:

Traceback (most recent call last):
  File "/usr/local/lib/python3.10/dist-packages/rnvs_tb/common.py", line 36, in log_wrapper
    return fun(*args, **kwargs)
  File "/usr/local/lib/python3.10/dist-packages/rnvs_tb/blocks/block5.py", line 733, in test_student_ring_set_set_get
    c1.await_packet(timeout=2.0)  # Wait for ACK before we query 2nd time
  File "/usr/local/lib/python3.10/dist-packages/rnvs_tb/mock.py", line 105, in await_packet
    raise AssertionError('Did not receive expected packet due to previous errors!') from value
AssertionError: Did not receive expected packet due to previous errors!

======================================================================
FAIL: test_trigger_get_minimal (rnvs_tb.blocks.block5.PeerTestCase)
Test whether a Client GET request triggers a proxy-GET request to the successor.
----------------------------------------------------------------------
Traceback (most recent call last):
  File "/usr/local/lib/python3.10/dist-packages/rnvs_tb/common.py", line 36, in log_wrapper
    return fun(*args, **kwargs)
  File "/usr/local/lib/python3.10/dist-packages/rnvs_tb/blocks/block5.py", line 230, in test_trigger_get_minimal
    self.fail(f"Did not receive a GET request within timeout! Stdout: {out}, Stderr:{err}")
AssertionError: Did not receive a GET request within timeout! Stdout: bytearray(b''), Stderr:bytearray(b'Starting server. Press any key to exit.\nDecoded packet header: \n\tACK: 0\n\tGET: 1\n\tSET: 0\n\tDEL: 0\n\tKey Length: 12 Bytes\n\tValue Length: 0 Bytes\nHash id: 18281\nWe are responsible.\n')

======================================================================
FAIL: test_trigger_lookup_minimal (rnvs_tb.blocks.block5.PeerTestCase)
Test whether a GET request from an unknown range triggers a lookup.
----------------------------------------------------------------------
Traceback (most recent call last):
  File "/usr/local/lib/python3.10/dist-packages/rnvs_tb/common.py", line 36, in log_wrapper
    return fun(*args, **kwargs)
  File "/usr/local/lib/python3.10/dist-packages/rnvs_tb/blocks/block5.py", line 193, in test_trigger_lookup_minimal
    self.fail(msg=f"Did not receive a lookup request within timeout! Stdout: {out}, Stderr:{err}")
AssertionError: Did not receive a lookup request within timeout! Stdout: bytearray(b''), Stderr:bytearray(b'Starting server. Press any key to exit.\nDecoded packet header: \n\tACK: 0\n\tGET: 1\n\tSET: 0\n\tDEL: 0\n\tKey Length: 18 Bytes\n\tValue Length: 0 Bytes\nHash id: 21618\nWe are responsible.\n')

----------------------------------------------------------------------
Ran 11 tests in 63.838s

FAILED (failures=11)
